try{
    let x = 10; 
    let y = 0;
    console.log(x/y);
}
catch(err){
    console.log(err);
}
console.log('After the catch block');